[2023-07-22T11:19:39.423+0000] {processor.py:157} INFO - Started process (PID=257) to work on /opt/airflow/dags/bs_disaster_dag.py
[2023-07-22T11:19:39.428+0000] {processor.py:826} INFO - Processing file /opt/airflow/dags/bs_disaster_dag.py for tasks to queue
[2023-07-22T11:19:39.430+0000] {logging_mixin.py:150} INFO - [2023-07-22T11:19:39.430+0000] {dagbag.py:541} INFO - Filling up the DagBag from /opt/airflow/dags/bs_disaster_dag.py
[2023-07-22T11:19:39.710+0000] {logging_mixin.py:150} INFO - [2023-07-22T11:19:39.680+0000] {dagbag.py:350} ERROR - Failed to import: /opt/airflow/dags/bs_disaster_dag.py
Traceback (most recent call last):
  File "/home/airflow/.local/lib/python3.7/site-packages/airflow/models/dagbag.py", line 346, in parse
    loader.exec_module(new_module)
  File "<frozen importlib._bootstrap_external>", line 728, in exec_module
  File "<frozen importlib._bootstrap>", line 219, in _call_with_frames_removed
  File "/opt/airflow/dags/bs_disaster_dag.py", line 14, in <module>
    DATASET_ID = Variable.get("DATASET_ID")
  File "/home/airflow/.local/lib/python3.7/site-packages/airflow/models/variable.py", line 142, in get
    raise KeyError(f"Variable {key} does not exist")
KeyError: 'Variable DATASET_ID does not exist'
[2023-07-22T11:19:39.744+0000] {processor.py:838} WARNING - No viable dags retrieved from /opt/airflow/dags/bs_disaster_dag.py
[2023-07-22T11:19:39.886+0000] {processor.py:179} INFO - Processing /opt/airflow/dags/bs_disaster_dag.py took 0.463 seconds
[2023-07-22T11:20:10.344+0000] {processor.py:157} INFO - Started process (PID=292) to work on /opt/airflow/dags/bs_disaster_dag.py
[2023-07-22T11:20:10.351+0000] {processor.py:826} INFO - Processing file /opt/airflow/dags/bs_disaster_dag.py for tasks to queue
[2023-07-22T11:20:10.354+0000] {logging_mixin.py:150} INFO - [2023-07-22T11:20:10.354+0000] {dagbag.py:541} INFO - Filling up the DagBag from /opt/airflow/dags/bs_disaster_dag.py
[2023-07-22T11:20:10.410+0000] {logging_mixin.py:150} INFO - [2023-07-22T11:20:10.406+0000] {dagbag.py:350} ERROR - Failed to import: /opt/airflow/dags/bs_disaster_dag.py
Traceback (most recent call last):
  File "/home/airflow/.local/lib/python3.7/site-packages/airflow/models/dagbag.py", line 346, in parse
    loader.exec_module(new_module)
  File "<frozen importlib._bootstrap_external>", line 728, in exec_module
  File "<frozen importlib._bootstrap>", line 219, in _call_with_frames_removed
  File "/opt/airflow/dags/bs_disaster_dag.py", line 14, in <module>
    DATASET_ID = Variable.get("DATASET_ID")
  File "/home/airflow/.local/lib/python3.7/site-packages/airflow/models/variable.py", line 142, in get
    raise KeyError(f"Variable {key} does not exist")
KeyError: 'Variable DATASET_ID does not exist'
[2023-07-22T11:20:10.411+0000] {processor.py:838} WARNING - No viable dags retrieved from /opt/airflow/dags/bs_disaster_dag.py
[2023-07-22T11:20:10.433+0000] {processor.py:179} INFO - Processing /opt/airflow/dags/bs_disaster_dag.py took 0.107 seconds
[2023-07-22T11:20:40.956+0000] {processor.py:157} INFO - Started process (PID=317) to work on /opt/airflow/dags/bs_disaster_dag.py
[2023-07-22T11:20:40.957+0000] {processor.py:826} INFO - Processing file /opt/airflow/dags/bs_disaster_dag.py for tasks to queue
[2023-07-22T11:20:40.959+0000] {logging_mixin.py:150} INFO - [2023-07-22T11:20:40.959+0000] {dagbag.py:541} INFO - Filling up the DagBag from /opt/airflow/dags/bs_disaster_dag.py
[2023-07-22T11:20:40.988+0000] {logging_mixin.py:150} INFO - [2023-07-22T11:20:40.986+0000] {dagbag.py:350} ERROR - Failed to import: /opt/airflow/dags/bs_disaster_dag.py
Traceback (most recent call last):
  File "/home/airflow/.local/lib/python3.7/site-packages/airflow/models/dagbag.py", line 346, in parse
    loader.exec_module(new_module)
  File "<frozen importlib._bootstrap_external>", line 728, in exec_module
  File "<frozen importlib._bootstrap>", line 219, in _call_with_frames_removed
  File "/opt/airflow/dags/bs_disaster_dag.py", line 14, in <module>
    DATASET_ID = Variable.get("DATASET_ID")
  File "/home/airflow/.local/lib/python3.7/site-packages/airflow/models/variable.py", line 142, in get
    raise KeyError(f"Variable {key} does not exist")
KeyError: 'Variable DATASET_ID does not exist'
[2023-07-22T11:20:40.989+0000] {processor.py:838} WARNING - No viable dags retrieved from /opt/airflow/dags/bs_disaster_dag.py
[2023-07-22T11:20:41.006+0000] {processor.py:179} INFO - Processing /opt/airflow/dags/bs_disaster_dag.py took 0.054 seconds
[2023-07-22T11:21:11.081+0000] {processor.py:157} INFO - Started process (PID=342) to work on /opt/airflow/dags/bs_disaster_dag.py
[2023-07-22T11:21:11.084+0000] {processor.py:826} INFO - Processing file /opt/airflow/dags/bs_disaster_dag.py for tasks to queue
[2023-07-22T11:21:11.087+0000] {logging_mixin.py:150} INFO - [2023-07-22T11:21:11.086+0000] {dagbag.py:541} INFO - Filling up the DagBag from /opt/airflow/dags/bs_disaster_dag.py
[2023-07-22T11:21:11.129+0000] {logging_mixin.py:150} INFO - [2023-07-22T11:21:11.124+0000] {dagbag.py:350} ERROR - Failed to import: /opt/airflow/dags/bs_disaster_dag.py
Traceback (most recent call last):
  File "/home/airflow/.local/lib/python3.7/site-packages/airflow/models/dagbag.py", line 346, in parse
    loader.exec_module(new_module)
  File "<frozen importlib._bootstrap_external>", line 728, in exec_module
  File "<frozen importlib._bootstrap>", line 219, in _call_with_frames_removed
  File "/opt/airflow/dags/bs_disaster_dag.py", line 14, in <module>
    DATASET_ID = Variable.get("DATASET_ID")
  File "/home/airflow/.local/lib/python3.7/site-packages/airflow/models/variable.py", line 142, in get
    raise KeyError(f"Variable {key} does not exist")
KeyError: 'Variable DATASET_ID does not exist'
[2023-07-22T11:21:11.131+0000] {processor.py:838} WARNING - No viable dags retrieved from /opt/airflow/dags/bs_disaster_dag.py
[2023-07-22T11:21:11.152+0000] {processor.py:179} INFO - Processing /opt/airflow/dags/bs_disaster_dag.py took 0.077 seconds
