[2023-07-22T11:19:40.875+0000] {processor.py:157} INFO - Started process (PID=269) to work on /opt/airflow/dags/bs_reviews_dag.py
[2023-07-22T11:19:40.885+0000] {processor.py:826} INFO - Processing file /opt/airflow/dags/bs_reviews_dag.py for tasks to queue
[2023-07-22T11:19:40.890+0000] {logging_mixin.py:150} INFO - [2023-07-22T11:19:40.887+0000] {dagbag.py:541} INFO - Filling up the DagBag from /opt/airflow/dags/bs_reviews_dag.py
[2023-07-22T11:19:41.024+0000] {logging_mixin.py:150} INFO - [2023-07-22T11:19:41.023+0000] {dagbag.py:350} ERROR - Failed to import: /opt/airflow/dags/bs_reviews_dag.py
Traceback (most recent call last):
  File "/home/airflow/.local/lib/python3.7/site-packages/airflow/models/dagbag.py", line 346, in parse
    loader.exec_module(new_module)
  File "<frozen importlib._bootstrap_external>", line 728, in exec_module
  File "<frozen importlib._bootstrap>", line 219, in _call_with_frames_removed
  File "/opt/airflow/dags/bs_reviews_dag.py", line 15, in <module>
    DATASET_ID = Variable.get("DATASET_ID")
  File "/home/airflow/.local/lib/python3.7/site-packages/airflow/models/variable.py", line 142, in get
    raise KeyError(f"Variable {key} does not exist")
KeyError: 'Variable DATASET_ID does not exist'
[2023-07-22T11:19:41.025+0000] {processor.py:838} WARNING - No viable dags retrieved from /opt/airflow/dags/bs_reviews_dag.py
[2023-07-22T11:19:41.065+0000] {processor.py:179} INFO - Processing /opt/airflow/dags/bs_reviews_dag.py took 0.199 seconds
[2023-07-22T11:20:11.686+0000] {processor.py:157} INFO - Started process (PID=297) to work on /opt/airflow/dags/bs_reviews_dag.py
[2023-07-22T11:20:11.687+0000] {processor.py:826} INFO - Processing file /opt/airflow/dags/bs_reviews_dag.py for tasks to queue
[2023-07-22T11:20:11.689+0000] {logging_mixin.py:150} INFO - [2023-07-22T11:20:11.688+0000] {dagbag.py:541} INFO - Filling up the DagBag from /opt/airflow/dags/bs_reviews_dag.py
[2023-07-22T11:20:11.717+0000] {logging_mixin.py:150} INFO - [2023-07-22T11:20:11.715+0000] {dagbag.py:350} ERROR - Failed to import: /opt/airflow/dags/bs_reviews_dag.py
Traceback (most recent call last):
  File "/home/airflow/.local/lib/python3.7/site-packages/airflow/models/dagbag.py", line 346, in parse
    loader.exec_module(new_module)
  File "<frozen importlib._bootstrap_external>", line 728, in exec_module
  File "<frozen importlib._bootstrap>", line 219, in _call_with_frames_removed
  File "/opt/airflow/dags/bs_reviews_dag.py", line 15, in <module>
    DATASET_ID = Variable.get("DATASET_ID")
  File "/home/airflow/.local/lib/python3.7/site-packages/airflow/models/variable.py", line 142, in get
    raise KeyError(f"Variable {key} does not exist")
KeyError: 'Variable DATASET_ID does not exist'
[2023-07-22T11:20:11.718+0000] {processor.py:838} WARNING - No viable dags retrieved from /opt/airflow/dags/bs_reviews_dag.py
[2023-07-22T11:20:11.736+0000] {processor.py:179} INFO - Processing /opt/airflow/dags/bs_reviews_dag.py took 0.055 seconds
[2023-07-22T11:20:42.305+0000] {processor.py:157} INFO - Started process (PID=322) to work on /opt/airflow/dags/bs_reviews_dag.py
[2023-07-22T11:20:42.307+0000] {processor.py:826} INFO - Processing file /opt/airflow/dags/bs_reviews_dag.py for tasks to queue
[2023-07-22T11:20:42.308+0000] {logging_mixin.py:150} INFO - [2023-07-22T11:20:42.307+0000] {dagbag.py:541} INFO - Filling up the DagBag from /opt/airflow/dags/bs_reviews_dag.py
[2023-07-22T11:20:42.341+0000] {logging_mixin.py:150} INFO - [2023-07-22T11:20:42.339+0000] {dagbag.py:350} ERROR - Failed to import: /opt/airflow/dags/bs_reviews_dag.py
Traceback (most recent call last):
  File "/home/airflow/.local/lib/python3.7/site-packages/airflow/models/dagbag.py", line 346, in parse
    loader.exec_module(new_module)
  File "<frozen importlib._bootstrap_external>", line 728, in exec_module
  File "<frozen importlib._bootstrap>", line 219, in _call_with_frames_removed
  File "/opt/airflow/dags/bs_reviews_dag.py", line 15, in <module>
    DATASET_ID = Variable.get("DATASET_ID")
  File "/home/airflow/.local/lib/python3.7/site-packages/airflow/models/variable.py", line 142, in get
    raise KeyError(f"Variable {key} does not exist")
KeyError: 'Variable DATASET_ID does not exist'
[2023-07-22T11:20:42.342+0000] {processor.py:838} WARNING - No viable dags retrieved from /opt/airflow/dags/bs_reviews_dag.py
[2023-07-22T11:20:42.358+0000] {processor.py:179} INFO - Processing /opt/airflow/dags/bs_reviews_dag.py took 0.058 seconds
[2023-07-22T11:21:13.538+0000] {processor.py:157} INFO - Started process (PID=356) to work on /opt/airflow/dags/bs_reviews_dag.py
[2023-07-22T11:21:13.542+0000] {processor.py:826} INFO - Processing file /opt/airflow/dags/bs_reviews_dag.py for tasks to queue
[2023-07-22T11:21:13.548+0000] {logging_mixin.py:150} INFO - [2023-07-22T11:21:13.547+0000] {dagbag.py:541} INFO - Filling up the DagBag from /opt/airflow/dags/bs_reviews_dag.py
[2023-07-22T11:21:13.627+0000] {logging_mixin.py:150} INFO - [2023-07-22T11:21:13.625+0000] {dagbag.py:350} ERROR - Failed to import: /opt/airflow/dags/bs_reviews_dag.py
Traceback (most recent call last):
  File "/home/airflow/.local/lib/python3.7/site-packages/airflow/models/dagbag.py", line 346, in parse
    loader.exec_module(new_module)
  File "<frozen importlib._bootstrap_external>", line 728, in exec_module
  File "<frozen importlib._bootstrap>", line 219, in _call_with_frames_removed
  File "/opt/airflow/dags/bs_reviews_dag.py", line 15, in <module>
    DATASET_ID = Variable.get("DATASET_ID")
  File "/home/airflow/.local/lib/python3.7/site-packages/airflow/models/variable.py", line 142, in get
    raise KeyError(f"Variable {key} does not exist")
KeyError: 'Variable DATASET_ID does not exist'
[2023-07-22T11:21:13.629+0000] {processor.py:838} WARNING - No viable dags retrieved from /opt/airflow/dags/bs_reviews_dag.py
[2023-07-22T11:21:13.687+0000] {processor.py:179} INFO - Processing /opt/airflow/dags/bs_reviews_dag.py took 0.154 seconds
