[2023-07-22T09:00:03.910+0000] {taskinstance.py:1103} INFO - Dependencies all met for dep_context=non-requeueable deps ti=<TaskInstance: data_ingestion_final_project.dbt_init_task manual__2023-07-22T08:44:18.483832+00:00 [queued]>
[2023-07-22T09:00:03.925+0000] {taskinstance.py:1103} INFO - Dependencies all met for dep_context=requeueable deps ti=<TaskInstance: data_ingestion_final_project.dbt_init_task manual__2023-07-22T08:44:18.483832+00:00 [queued]>
[2023-07-22T09:00:03.925+0000] {taskinstance.py:1308} INFO - Starting attempt 1 of 2
[2023-07-22T09:00:03.946+0000] {taskinstance.py:1327} INFO - Executing <Task(BashOperator): dbt_init_task> on 2023-07-22 08:44:18.483832+00:00
[2023-07-22T09:00:03.956+0000] {standard_task_runner.py:57} INFO - Started process 2580 to run task
[2023-07-22T09:00:03.961+0000] {standard_task_runner.py:84} INFO - Running: ['***', 'tasks', 'run', 'data_ingestion_final_project', 'dbt_init_task', 'manual__2023-07-22T08:44:18.483832+00:00', '--job-id', '88', '--raw', '--subdir', 'DAGS_FOLDER/data_ingestion_final_project.py', '--cfg-path', '/tmp/tmp04hd1052']
[2023-07-22T09:00:03.965+0000] {standard_task_runner.py:85} INFO - Job 88: Subtask dbt_init_task
[2023-07-22T09:00:03.985+0000] {warnings.py:110} WARNING - /home/***/.local/lib/python3.7/site-packages/***/settings.py:195: DeprecationWarning: The sql_alchemy_conn option in [core] has been moved to the sql_alchemy_conn option in [database] - the old setting has been used, but please update your config.
  SQL_ALCHEMY_CONN = conf.get("database", "SQL_ALCHEMY_CONN")

[2023-07-22T09:00:04.046+0000] {task_command.py:410} INFO - Running <TaskInstance: data_ingestion_final_project.dbt_init_task manual__2023-07-22T08:44:18.483832+00:00 [running]> on host 06435c559ff5
[2023-07-22T09:00:04.190+0000] {taskinstance.py:1547} INFO - Exporting env vars: AIRFLOW_CTX_DAG_OWNER='***' AIRFLOW_CTX_DAG_ID='data_ingestion_final_project' AIRFLOW_CTX_TASK_ID='dbt_init_task' AIRFLOW_CTX_EXECUTION_DATE='2023-07-22T08:44:18.483832+00:00' AIRFLOW_CTX_TRY_NUMBER='1' AIRFLOW_CTX_DAG_RUN_ID='manual__2023-07-22T08:44:18.483832+00:00'
[2023-07-22T09:00:04.193+0000] {subprocess.py:63} INFO - Tmp dir root location: /tmp
[2023-07-22T09:00:04.196+0000] {subprocess.py:75} INFO - Running command: ['/bin/bash', '-c', 'cd /opt/***/dbt/credit_card_dwh && dbt deps && dbt seed --profiles-dir .']
[2023-07-22T09:00:04.222+0000] {subprocess.py:86} INFO - Output:
[2023-07-22T09:00:13.332+0000] {subprocess.py:93} INFO - [0m09:00:13  Running with dbt=1.5.3
[2023-07-22T09:00:14.796+0000] {subprocess.py:93} INFO - [0m09:00:14  Installing dbt-labs/dbt_utils
[2023-07-22T09:00:17.205+0000] {subprocess.py:93} INFO - [0m09:00:17  Installed from version 0.8.0
[2023-07-22T09:00:17.219+0000] {subprocess.py:93} INFO - [0m09:00:17  Updated version available: 1.1.1
[2023-07-22T09:00:17.231+0000] {subprocess.py:93} INFO - [0m09:00:17  Installing calogica/dbt_expectations
[2023-07-22T09:00:19.127+0000] {subprocess.py:93} INFO - [0m09:00:19  Installed from version 0.8.5
[2023-07-22T09:00:19.131+0000] {subprocess.py:93} INFO - [0m09:00:19  Up to date!
[2023-07-22T09:00:19.137+0000] {subprocess.py:93} INFO - [0m09:00:19  Installing calogica/dbt_date
[2023-07-22T09:00:19.756+0000] {subprocess.py:93} INFO - [0m09:00:19  Installed from version 0.7.2
[2023-07-22T09:00:19.758+0000] {subprocess.py:93} INFO - [0m09:00:19  Up to date!
[2023-07-22T09:00:19.763+0000] {subprocess.py:93} INFO - [0m09:00:19
[2023-07-22T09:00:19.767+0000] {subprocess.py:93} INFO - [0m09:00:19  Updates available for packages: ['dbt-labs/dbt_utils']
[2023-07-22T09:00:19.768+0000] {subprocess.py:93} INFO - Update your versions in packages.yml, then run dbt deps
[2023-07-22T09:00:25.969+0000] {subprocess.py:93} INFO - [0m09:00:25  Running with dbt=1.5.3
[2023-07-22T09:00:25.976+0000] {subprocess.py:93} INFO - [0m09:00:25  Encountered an error:
[2023-07-22T09:00:25.987+0000] {subprocess.py:93} INFO - Runtime Error
[2023-07-22T09:00:25.987+0000] {subprocess.py:93} INFO -   Could not find profile named 'bank_campaign_dwh'
[2023-07-22T09:00:27.637+0000] {subprocess.py:97} INFO - Command exited with return code 2
[2023-07-22T09:00:27.651+0000] {taskinstance.py:1824} ERROR - Task failed with exception
Traceback (most recent call last):
  File "/home/airflow/.local/lib/python3.7/site-packages/airflow/operators/bash.py", line 211, in execute
    f"Bash command failed. The command returned a non-zero exit code {result.exit_code}."
airflow.exceptions.AirflowException: Bash command failed. The command returned a non-zero exit code 2.
[2023-07-22T09:00:27.658+0000] {taskinstance.py:1350} INFO - Marking task as UP_FOR_RETRY. dag_id=data_ingestion_final_project, task_id=dbt_init_task, execution_date=20230722T084418, start_date=20230722T090003, end_date=20230722T090027
[2023-07-22T09:00:27.674+0000] {standard_task_runner.py:109} ERROR - Failed to execute job 88 for task dbt_init_task (Bash command failed. The command returned a non-zero exit code 2.; 2580)
[2023-07-22T09:00:27.698+0000] {local_task_job_runner.py:225} INFO - Task exited with return code 1
[2023-07-22T09:00:27.729+0000] {taskinstance.py:2653} INFO - 0 downstream tasks scheduled from follow-on schedule check
