[2023-07-26T16:15:03.268+0000] {taskinstance.py:1103} INFO - Dependencies all met for dep_context=non-requeueable deps ti=<TaskInstance: data_ingestion-pq.add_gcp_conn_task manual__2023-07-26T16:09:45.132166+00:00 [queued]>
[2023-07-26T16:15:03.283+0000] {taskinstance.py:1103} INFO - Dependencies all met for dep_context=requeueable deps ti=<TaskInstance: data_ingestion-pq.add_gcp_conn_task manual__2023-07-26T16:09:45.132166+00:00 [queued]>
[2023-07-26T16:15:03.284+0000] {taskinstance.py:1308} INFO - Starting attempt 2 of 2
[2023-07-26T16:15:03.310+0000] {taskinstance.py:1327} INFO - Executing <Task(PythonOperator): add_gcp_conn_task> on 2023-07-26 16:09:45.132166+00:00
[2023-07-26T16:15:03.317+0000] {standard_task_runner.py:57} INFO - Started process 420 to run task
[2023-07-26T16:15:03.325+0000] {standard_task_runner.py:84} INFO - Running: ['***', 'tasks', 'run', 'data_ingestion-pq', 'add_gcp_conn_task', 'manual__2023-07-26T16:09:45.132166+00:00', '--job-id', '20', '--raw', '--subdir', 'DAGS_FOLDER/data_ingest_pq.py', '--cfg-path', '/tmp/tmp3sbmr8qq']
[2023-07-26T16:15:03.333+0000] {standard_task_runner.py:85} INFO - Job 20: Subtask add_gcp_conn_task
[2023-07-26T16:15:03.352+0000] {warnings.py:110} WARNING - /home/***/.local/lib/python3.7/site-packages/***/settings.py:195: DeprecationWarning: The sql_alchemy_conn option in [core] has been moved to the sql_alchemy_conn option in [database] - the old setting has been used, but please update your config.
  SQL_ALCHEMY_CONN = conf.get("database", "SQL_ALCHEMY_CONN")

[2023-07-26T16:15:03.409+0000] {task_command.py:410} INFO - Running <TaskInstance: data_ingestion-pq.add_gcp_conn_task manual__2023-07-26T16:09:45.132166+00:00 [running]> on host e35a35833287
[2023-07-26T16:15:03.546+0000] {taskinstance.py:1547} INFO - Exporting env vars: AIRFLOW_CTX_DAG_OWNER='***' AIRFLOW_CTX_DAG_ID='data_ingestion-pq' AIRFLOW_CTX_TASK_ID='add_gcp_conn_task' AIRFLOW_CTX_EXECUTION_DATE='2023-07-26T16:09:45.132166+00:00' AIRFLOW_CTX_TRY_NUMBER='2' AIRFLOW_CTX_DAG_RUN_ID='manual__2023-07-26T16:09:45.132166+00:00'
[2023-07-26T16:15:03.549+0000] {crypto.py:83} WARNING - empty cryptography key - values will not be stored encrypted.
[2023-07-26T16:15:03.569+0000] {base.py:73} INFO - Using connection ID 'my_gcp_conn' for task execution.
[2023-07-26T16:15:03.586+0000] {taskinstance.py:1824} ERROR - Task failed with exception
Traceback (most recent call last):
  File "/home/airflow/.local/lib/python3.7/site-packages/sqlalchemy/engine/base.py", line 1911, in _execute_context
    cursor, statement, parameters, context
  File "/home/airflow/.local/lib/python3.7/site-packages/sqlalchemy/engine/default.py", line 736, in do_execute
    cursor.execute(statement, parameters)
psycopg2.errors.UniqueViolation: duplicate key value violates unique constraint "connection_conn_id_uq"
DETAIL:  Key (conn_id)=(my_gcp_conn) already exists.


The above exception was the direct cause of the following exception:

Traceback (most recent call last):
  File "/home/airflow/.local/lib/python3.7/site-packages/airflow/operators/python.py", line 181, in execute
    return_value = self.execute_callable()
  File "/home/airflow/.local/lib/python3.7/site-packages/airflow/operators/python.py", line 198, in execute_callable
    return self.python_callable(*self.op_args, **self.op_kwargs)
  File "/opt/airflow/dags/data_ingest_pq.py", line 79, in add_gcp_connection
    session.commit()
  File "/home/airflow/.local/lib/python3.7/site-packages/sqlalchemy/orm/session.py", line 1454, in commit
    self._transaction.commit(_to_root=self.future)
  File "/home/airflow/.local/lib/python3.7/site-packages/sqlalchemy/orm/session.py", line 832, in commit
    self._prepare_impl()
  File "/home/airflow/.local/lib/python3.7/site-packages/sqlalchemy/orm/session.py", line 811, in _prepare_impl
    self.session.flush()
  File "/home/airflow/.local/lib/python3.7/site-packages/sqlalchemy/orm/session.py", line 3449, in flush
    self._flush(objects)
  File "/home/airflow/.local/lib/python3.7/site-packages/sqlalchemy/orm/session.py", line 3589, in _flush
    transaction.rollback(_capture_exception=True)
  File "/home/airflow/.local/lib/python3.7/site-packages/sqlalchemy/util/langhelpers.py", line 72, in __exit__
    with_traceback=exc_tb,
  File "/home/airflow/.local/lib/python3.7/site-packages/sqlalchemy/util/compat.py", line 211, in raise_
    raise exception
  File "/home/airflow/.local/lib/python3.7/site-packages/sqlalchemy/orm/session.py", line 3549, in _flush
    flush_context.execute()
  File "/home/airflow/.local/lib/python3.7/site-packages/sqlalchemy/orm/unitofwork.py", line 456, in execute
    rec.execute(self)
  File "/home/airflow/.local/lib/python3.7/site-packages/sqlalchemy/orm/unitofwork.py", line 633, in execute
    uow,
  File "/home/airflow/.local/lib/python3.7/site-packages/sqlalchemy/orm/persistence.py", line 250, in save_obj
    insert,
  File "/home/airflow/.local/lib/python3.7/site-packages/sqlalchemy/orm/persistence.py", line 1241, in _emit_insert_statements
    execution_options=execution_options,
  File "/home/airflow/.local/lib/python3.7/site-packages/sqlalchemy/engine/base.py", line 1710, in _execute_20
    return meth(self, args_10style, kwargs_10style, execution_options)
  File "/home/airflow/.local/lib/python3.7/site-packages/sqlalchemy/sql/elements.py", line 335, in _execute_on_connection
    self, multiparams, params, execution_options
  File "/home/airflow/.local/lib/python3.7/site-packages/sqlalchemy/engine/base.py", line 1587, in _execute_clauseelement
    cache_hit=cache_hit,
  File "/home/airflow/.local/lib/python3.7/site-packages/sqlalchemy/engine/base.py", line 1954, in _execute_context
    e, statement, parameters, cursor, context
  File "/home/airflow/.local/lib/python3.7/site-packages/sqlalchemy/engine/base.py", line 2135, in _handle_dbapi_exception
    sqlalchemy_exception, with_traceback=exc_info[2], from_=e
  File "/home/airflow/.local/lib/python3.7/site-packages/sqlalchemy/util/compat.py", line 211, in raise_
    raise exception
  File "/home/airflow/.local/lib/python3.7/site-packages/sqlalchemy/engine/base.py", line 1911, in _execute_context
    cursor, statement, parameters, context
  File "/home/airflow/.local/lib/python3.7/site-packages/sqlalchemy/engine/default.py", line 736, in do_execute
    cursor.execute(statement, parameters)
sqlalchemy.exc.IntegrityError: (psycopg2.errors.UniqueViolation) duplicate key value violates unique constraint "connection_conn_id_uq"
DETAIL:  Key (conn_id)=(my_gcp_conn) already exists.

[SQL: INSERT INTO connection (conn_id, conn_type, description, host, schema, login, password, port, is_encrypted, is_extra_encrypted, extra) VALUES (%(conn_id)s, %(conn_type)s, %(description)s, %(host)s, %(schema)s, %(login)s, %(password)s, %(port)s, %(is_encrypted)s, %(is_extra_encrypted)s, %(extra)s) RETURNING connection.id]
[parameters: {'conn_id': 'my_gcp_conn', 'conn_type': 'google_cloud_platform', 'description': None, 'host': None, 'schema': None, 'login': None, 'password': None, 'port': None, 'is_encrypted': False, 'is_extra_encrypted': False, 'extra': '{"extra__google_cloud_platform__key_path": "/opt/airflow/service-account.json", "extra__google_cloud_platform__project": "snappy-lattice-393408", "extra__google_cloud_platform__scope": "https://www.googleapis.com/auth/cloud-platform"}'}]
(Background on this error at: https://sqlalche.me/e/14/gkpj)
[2023-07-26T16:15:03.599+0000] {standard_task_runner.py:109} ERROR - Failed to execute job 20 for task add_gcp_conn_task (This Session's transaction has been rolled back due to a previous exception during flush. To begin a new transaction with this Session, first issue Session.rollback(). Original exception was: (psycopg2.errors.UniqueViolation) duplicate key value violates unique constraint "connection_conn_id_uq"
DETAIL:  Key (conn_id)=(my_gcp_conn) already exists.

[SQL: INSERT INTO connection (conn_id, conn_type, description, host, schema, login, password, port, is_encrypted, is_extra_encrypted, extra) VALUES (%(conn_id)s, %(conn_type)s, %(description)s, %(host)s, %(schema)s, %(login)s, %(password)s, %(port)s, %(is_encrypted)s, %(is_extra_encrypted)s, %(extra)s) RETURNING connection.id]
[parameters: {'conn_id': 'my_gcp_conn', 'conn_type': 'google_cloud_platform', 'description': None, 'host': None, 'schema': None, 'login': None, 'password': None, 'port': None, 'is_encrypted': False, 'is_extra_encrypted': False, 'extra': '{"extra__google_cloud_platform__key_path": "/opt/airflow/service-account.json", "extra__google_cloud_platform__project": "snappy-lattice-393408", "extra__google_cloud_platform__scope": "https://www.googleapis.com/auth/cloud-platform"}'}]
(Background on this error at: https://sqlalche.me/e/14/gkpj) (Background on this error at: https://sqlalche.me/e/14/7s2a); 420)
[2023-07-26T16:15:03.616+0000] {local_task_job_runner.py:225} INFO - Task exited with return code 1
[2023-07-26T16:15:03.652+0000] {taskinstance.py:2653} INFO - 0 downstream tasks scheduled from follow-on schedule check
