[2023-07-22T08:25:18.892+0000] {taskinstance.py:1103} INFO - Dependencies all met for dep_context=non-requeueable deps ti=<TaskInstance: data_ingestion_final_project.load_gcs_to_bq manual__2023-07-22T08:24:35.751555+00:00 [queued]>
[2023-07-22T08:25:18.903+0000] {taskinstance.py:1103} INFO - Dependencies all met for dep_context=requeueable deps ti=<TaskInstance: data_ingestion_final_project.load_gcs_to_bq manual__2023-07-22T08:24:35.751555+00:00 [queued]>
[2023-07-22T08:25:18.904+0000] {taskinstance.py:1308} INFO - Starting attempt 1 of 2
[2023-07-22T08:25:18.921+0000] {taskinstance.py:1327} INFO - Executing <Task(GCSToBigQueryOperator): load_gcs_to_bq> on 2023-07-22 08:24:35.751555+00:00
[2023-07-22T08:25:18.928+0000] {standard_task_runner.py:57} INFO - Started process 787 to run task
[2023-07-22T08:25:18.933+0000] {standard_task_runner.py:84} INFO - Running: ['***', 'tasks', 'run', 'data_ingestion_final_project', 'load_gcs_to_bq', 'manual__2023-07-22T08:24:35.751555+00:00', '--job-id', '74', '--raw', '--subdir', 'DAGS_FOLDER/data_ingestion_final_project.py', '--cfg-path', '/tmp/tmp6r16g9e1']
[2023-07-22T08:25:18.936+0000] {standard_task_runner.py:85} INFO - Job 74: Subtask load_gcs_to_bq
[2023-07-22T08:25:18.952+0000] {warnings.py:110} WARNING - /home/***/.local/lib/python3.7/site-packages/***/settings.py:195: DeprecationWarning: The sql_alchemy_conn option in [core] has been moved to the sql_alchemy_conn option in [database] - the old setting has been used, but please update your config.
  SQL_ALCHEMY_CONN = conf.get("database", "SQL_ALCHEMY_CONN")

[2023-07-22T08:25:18.998+0000] {task_command.py:410} INFO - Running <TaskInstance: data_ingestion_final_project.load_gcs_to_bq manual__2023-07-22T08:24:35.751555+00:00 [running]> on host 06435c559ff5
[2023-07-22T08:25:19.109+0000] {taskinstance.py:1547} INFO - Exporting env vars: AIRFLOW_CTX_DAG_OWNER='***' AIRFLOW_CTX_DAG_ID='data_ingestion_final_project' AIRFLOW_CTX_TASK_ID='load_gcs_to_bq' AIRFLOW_CTX_EXECUTION_DATE='2023-07-22T08:24:35.751555+00:00' AIRFLOW_CTX_TRY_NUMBER='1' AIRFLOW_CTX_DAG_RUN_ID='manual__2023-07-22T08:24:35.751555+00:00'
[2023-07-22T08:25:19.123+0000] {base.py:73} INFO - Using connection ID 'my_gcp_conn' for task execution.
[2023-07-22T08:25:19.125+0000] {gcs_to_bigquery.py:373} INFO - Using existing BigQuery table for storing data...
[2023-07-22T08:25:19.129+0000] {taskinstance.py:1824} ERROR - Task failed with exception
Traceback (most recent call last):
  File "/home/airflow/.local/lib/python3.7/site-packages/airflow/providers/google/cloud/transfers/gcs_to_bigquery.py", line 374, in execute
    self.configuration = self._use_existing_table()
  File "/home/airflow/.local/lib/python3.7/site-packages/airflow/providers/google/cloud/transfers/gcs_to_bigquery.py", line 577, in _use_existing_table
    default_project_id=self.project_id or self.hook.project_id,
  File "/home/airflow/.local/lib/python3.7/site-packages/airflow/providers/google/common/hooks/base_google.py", line 348, in project_id
    _, project_id = self.get_credentials_and_project_id()
  File "/home/airflow/.local/lib/python3.7/site-packages/airflow/providers/google/common/hooks/base_google.py", line 267, in get_credentials_and_project_id
    delegates=delegates,
  File "/home/airflow/.local/lib/python3.7/site-packages/airflow/providers/google/cloud/utils/credentials_provider.py", line 332, in get_credentials_and_project_id
    return _CredentialProvider(*args, **kwargs).get_credentials_and_project()
  File "/home/airflow/.local/lib/python3.7/site-packages/airflow/providers/google/cloud/utils/credentials_provider.py", line 231, in get_credentials_and_project
    credentials, project_id = self._get_credentials_using_key_path()
  File "/home/airflow/.local/lib/python3.7/site-packages/airflow/providers/google/cloud/utils/credentials_provider.py", line 281, in _get_credentials_using_key_path
    self.key_path, scopes=self.scopes
  File "/home/airflow/.local/lib/python3.7/site-packages/google/oauth2/service_account.py", line 257, in from_service_account_file
    filename, require=["client_email", "token_uri"]
  File "/home/airflow/.local/lib/python3.7/site-packages/google/auth/_service_account_info.py", line 80, in from_filename
    with io.open(filename, "r", encoding="utf-8") as json_file:
FileNotFoundError: [Errno 2] No such file or directory: '/.google/credentials/google_credentials.json'
[2023-07-22T08:25:19.140+0000] {taskinstance.py:1350} INFO - Marking task as UP_FOR_RETRY. dag_id=data_ingestion_final_project, task_id=load_gcs_to_bq, execution_date=20230722T082435, start_date=20230722T082518, end_date=20230722T082519
[2023-07-22T08:25:19.153+0000] {standard_task_runner.py:109} ERROR - Failed to execute job 74 for task load_gcs_to_bq ([Errno 2] No such file or directory: '/.google/credentials/google_credentials.json'; 787)
[2023-07-22T08:25:19.184+0000] {local_task_job_runner.py:225} INFO - Task exited with return code 1
[2023-07-22T08:25:19.213+0000] {taskinstance.py:2653} INFO - 0 downstream tasks scheduled from follow-on schedule check
