[2023-07-27T04:52:18.946+0000] {taskinstance.py:1103} INFO - Dependencies all met for dep_context=non-requeueable deps ti=<TaskInstance: data_ingestion-pq.dbt_init_task manual__2023-07-26T16:09:45.132166+00:00 [queued]>
[2023-07-27T04:52:18.973+0000] {taskinstance.py:1103} INFO - Dependencies all met for dep_context=requeueable deps ti=<TaskInstance: data_ingestion-pq.dbt_init_task manual__2023-07-26T16:09:45.132166+00:00 [queued]>
[2023-07-27T04:52:18.975+0000] {taskinstance.py:1308} INFO - Starting attempt 10 of 11
[2023-07-27T04:52:19.030+0000] {taskinstance.py:1327} INFO - Executing <Task(BashOperator): dbt_init_task> on 2023-07-26 16:09:45.132166+00:00
[2023-07-27T04:52:19.042+0000] {standard_task_runner.py:57} INFO - Started process 116 to run task
[2023-07-27T04:52:19.054+0000] {standard_task_runner.py:84} INFO - Running: ['***', 'tasks', 'run', 'data_ingestion-pq', 'dbt_init_task', 'manual__2023-07-26T16:09:45.132166+00:00', '--job-id', '44', '--raw', '--subdir', 'DAGS_FOLDER/data_ingest_pq.py', '--cfg-path', '/tmp/tmpdrwfoma0']
[2023-07-27T04:52:19.062+0000] {standard_task_runner.py:85} INFO - Job 44: Subtask dbt_init_task
[2023-07-27T04:52:19.093+0000] {warnings.py:110} WARNING - /home/***/.local/lib/python3.7/site-packages/***/settings.py:195: DeprecationWarning: The sql_alchemy_conn option in [core] has been moved to the sql_alchemy_conn option in [database] - the old setting has been used, but please update your config.
  SQL_ALCHEMY_CONN = conf.get("database", "SQL_ALCHEMY_CONN")

[2023-07-27T04:52:19.178+0000] {task_command.py:410} INFO - Running <TaskInstance: data_ingestion-pq.dbt_init_task manual__2023-07-26T16:09:45.132166+00:00 [running]> on host e24602950393
[2023-07-27T04:52:19.360+0000] {taskinstance.py:1547} INFO - Exporting env vars: AIRFLOW_CTX_DAG_OWNER='***' AIRFLOW_CTX_DAG_ID='data_ingestion-pq' AIRFLOW_CTX_TASK_ID='dbt_init_task' AIRFLOW_CTX_EXECUTION_DATE='2023-07-26T16:09:45.132166+00:00' AIRFLOW_CTX_TRY_NUMBER='10' AIRFLOW_CTX_DAG_RUN_ID='manual__2023-07-26T16:09:45.132166+00:00'
[2023-07-27T04:52:19.363+0000] {subprocess.py:63} INFO - Tmp dir root location: /tmp
[2023-07-27T04:52:19.366+0000] {subprocess.py:75} INFO - Running command: ['/bin/bash', '-c', 'cd /opt/***/dbt/marketing_dwh && dbt deps && dbt seed --profiles-dir .']
[2023-07-27T04:52:19.390+0000] {subprocess.py:86} INFO - Output:
[2023-07-27T04:52:26.416+0000] {subprocess.py:93} INFO - [0m04:52:26  Running with dbt=1.5.3
[2023-07-27T04:52:26.464+0000] {subprocess.py:93} INFO - [0m04:52:26  Encountered an error:
[2023-07-27T04:52:26.464+0000] {subprocess.py:93} INFO - [Errno 13] Permission denied: 'dbt_packages'
[2023-07-27T04:52:26.469+0000] {subprocess.py:93} INFO - [0m04:52:26  Traceback (most recent call last):
[2023-07-27T04:52:26.470+0000] {subprocess.py:93} INFO -   File "/home/***/.local/lib/python3.7/site-packages/dbt/cli/requires.py", line 86, in wrapper
[2023-07-27T04:52:26.470+0000] {subprocess.py:93} INFO -     result, success = func(*args, **kwargs)
[2023-07-27T04:52:26.471+0000] {subprocess.py:93} INFO -   File "/home/***/.local/lib/python3.7/site-packages/dbt/cli/requires.py", line 71, in wrapper
[2023-07-27T04:52:26.471+0000] {subprocess.py:93} INFO -     return func(*args, **kwargs)
[2023-07-27T04:52:26.471+0000] {subprocess.py:93} INFO -   File "/home/***/.local/lib/python3.7/site-packages/dbt/cli/requires.py", line 125, in wrapper
[2023-07-27T04:52:26.472+0000] {subprocess.py:93} INFO -     return func(*args, **kwargs)
[2023-07-27T04:52:26.472+0000] {subprocess.py:93} INFO -   File "/home/***/.local/lib/python3.7/site-packages/dbt/cli/requires.py", line 168, in wrapper
[2023-07-27T04:52:26.472+0000] {subprocess.py:93} INFO -     return func(*args, **kwargs)
[2023-07-27T04:52:26.473+0000] {subprocess.py:93} INFO -   File "/home/***/.local/lib/python3.7/site-packages/dbt/cli/main.py", line 437, in deps
[2023-07-27T04:52:26.473+0000] {subprocess.py:93} INFO -     results = task.run()
[2023-07-27T04:52:26.474+0000] {subprocess.py:93} INFO -   File "/home/***/.local/lib/python3.7/site-packages/dbt/task/deps.py", line 63, in run
[2023-07-27T04:52:26.474+0000] {subprocess.py:93} INFO -     system.make_directory(self.project.packages_install_path)
[2023-07-27T04:52:26.474+0000] {subprocess.py:93} INFO -   File "/usr/local/lib/python3.7/functools.py", line 840, in wrapper
[2023-07-27T04:52:26.475+0000] {subprocess.py:93} INFO -     return dispatch(args[0].__class__)(*args, **kw)
[2023-07-27T04:52:26.475+0000] {subprocess.py:93} INFO -   File "/home/***/.local/lib/python3.7/site-packages/dbt/clients/system.py", line 128, in _
[2023-07-27T04:52:26.475+0000] {subprocess.py:93} INFO -     raise e
[2023-07-27T04:52:26.475+0000] {subprocess.py:93} INFO -   File "/home/***/.local/lib/python3.7/site-packages/dbt/clients/system.py", line 122, in _
[2023-07-27T04:52:26.476+0000] {subprocess.py:93} INFO -     os.makedirs(path)
[2023-07-27T04:52:26.476+0000] {subprocess.py:93} INFO -   File "/usr/local/lib/python3.7/os.py", line 223, in makedirs
[2023-07-27T04:52:26.476+0000] {subprocess.py:93} INFO -     mkdir(name, mode)
[2023-07-27T04:52:26.476+0000] {subprocess.py:93} INFO - PermissionError: [Errno 13] Permission denied: 'dbt_packages'
[2023-07-27T04:52:26.477+0000] {subprocess.py:93} INFO - 
[2023-07-27T04:52:29.720+0000] {subprocess.py:97} INFO - Command exited with return code 2
[2023-07-27T04:52:29.735+0000] {taskinstance.py:1824} ERROR - Task failed with exception
Traceback (most recent call last):
  File "/home/airflow/.local/lib/python3.7/site-packages/airflow/operators/bash.py", line 211, in execute
    f"Bash command failed. The command returned a non-zero exit code {result.exit_code}."
airflow.exceptions.AirflowException: Bash command failed. The command returned a non-zero exit code 2.
[2023-07-27T04:52:29.741+0000] {taskinstance.py:1350} INFO - Marking task as UP_FOR_RETRY. dag_id=data_ingestion-pq, task_id=dbt_init_task, execution_date=20230726T160945, start_date=20230727T045218, end_date=20230727T045229
[2023-07-27T04:52:29.765+0000] {standard_task_runner.py:109} ERROR - Failed to execute job 44 for task dbt_init_task (Bash command failed. The command returned a non-zero exit code 2.; 116)
[2023-07-27T04:52:29.807+0000] {local_task_job_runner.py:225} INFO - Task exited with return code 1
[2023-07-27T04:52:29.840+0000] {taskinstance.py:2653} INFO - 0 downstream tasks scheduled from follow-on schedule check
